<?xml version="1.0" ?>
<sdf version='1.11'>
  <model name="diff_drive">
    <self_collide>false</self_collide>

    <link name='frame_base_link'>
      <inertial>
        <pose>0.17458351182617299 -0.27053109467958703 0.17575916949314699 0 0 0</pose>
        <mass>10.5515252104505</mass>
        <inertia>
          <ixx>0.058754977849158299</ixx>
          <ixy>0</ixy>
          <ixz>0</ixz>
          <iyy>0.14573224118397901</iyy>
          <iyz>0</iyz>
          <izz>0.19676917764108701</izz>
        </inertia>
      </inertial>
      <collision name='frame_base_link_collision'>
        <pose>0 0 0 0 0 0</pose>
        <geometry>
          <mesh>
            <scale>1 1 1</scale>
            <uri>package://ros_gz_description/models/meshes/frame_base_link.STL</uri>
          </mesh>
        </geometry>
      </collision>
      <visual name='frame_base_link_visual'>
        <pose>0 0 0 0 0 0</pose>
        <geometry>
          <mesh>
            <scale>1 1 1</scale>
	    <uri>package://ros_gz_description/models/meshes/frame_base_link.STL</uri>
          </mesh>
        </geometry>
        <material>
          <diffuse>0.990196109 1 1 1</diffuse>
          <ambient>0.990196109 1 1 1</ambient>
        </material>
      </visual>
    </link>

    <joint name='wheel0_joint' type='revolute'>
      <pose relative_to='frame_base_link'>0.43724916124044599 -0.15540350026859401 0.13808211520538699 3.14159265358979 -0.45265961871145888 -1.5707963267949001</pose>
      <parent>frame_base_link</parent>
      <child>wheel0_link</child>
      <axis>
        <xyz>0 1 0</xyz>
        <limit>
          <lower>-inf</lower>
          <upper>inf</upper>
        </limit>
        <dynamics>
          <spring_reference>0</spring_reference>
          <spring_stiffness>0</spring_stiffness>
        </dynamics>
      </axis>
    </joint>

    <link name='wheel0_link'>
      <pose relative_to='wheel0_joint'>0 0 0 0 0 0</pose>
      <inertial>
        <pose>0 0 0 0 0 0</pose>
        <mass>0.34293000000000001</mass>
        <inertia>
          <ixx>0.00040793999999999997</ixx>
          <ixy>0</ixy>
          <ixz>0</ixz>
          <iyy>0.00069253999999999995</iyy>
          <iyz>0</iyz>
          <izz>0.00040793999999999997</izz>
        </inertia>
      </inertial>
      <collision name='wheel0_collision'>
        <pose>0 0 0 0 0 0</pose>
        <geometry>
          <mesh>
            <scale>1 1 1</scale>
            <uri>package://ros_gz_description/models/meshes/wheel0.STL</uri>
          </mesh>
        </geometry>
      </collision>
      <visual name='wheel0_visual'>
        <pose>0 0 0 0 0 0</pose>
        <geometry>
          <mesh>
            <scale>1 1 1</scale>
            <uri>package://ros_gz_description/models/meshes/wheel0.STL</uri>
          </mesh>
        </geometry>
        <material>
          <diffuse>1 1 1 1</diffuse>
          <ambient>1 1 1 1</ambient>
        </material>
      </visual>
    </link>

    <joint name='wheel1_joint' type='revolute'>
      <pose relative_to='frame_base_link'>-0.087154396196859801 -0.15540350026859401 0.13808211520538699 0 1.0045642209358503 -1.5707963267949001</pose>
      <parent>frame_base_link</parent>
      <child>wheel1_link</child>
      <axis>
        <xyz>0 -1 0</xyz>
        <limit>
          <lower>-inf</lower>
          <upper>inf</upper>
        </limit>
        <dynamics>
          <spring_reference>0</spring_reference>
          <spring_stiffness>0</spring_stiffness>
        </dynamics>
      </axis>
    </joint>

    <link name='wheel1_link'>
      <pose relative_to='wheel1_joint'>0 0 0 0 0 0</pose>
      <inertial>
        <pose>0 0 0 0 0 0</pose>
        <mass>0.34293000000000001</mass>
        <inertia>
          <ixx>0.00040793999999999997</ixx>
          <ixy>0</ixy>
          <ixz>0</ixz>
          <iyy>0.00069253999999999995</iyy>
          <iyz>0</iyz>
          <izz>0.00040793999999999997</izz>
        </inertia>
      </inertial>
      <collision name='wheel1_collision'>
        <pose>0 0 0 0 0 0</pose>
        <geometry>
          <mesh>
            <scale>1 1 1</scale>
            <uri>package://ros_gz_description/models/meshes/wheel1.STL</uri>
          </mesh>
        </geometry>
      </collision>
      <visual name='wheel1_visual'>
        <pose>0 0 0 0 0 0</pose>
        <geometry>
          <mesh>
            <scale>1 1 1</scale>
            <uri>package://ros_gz_description/models/meshes/wheel1.STL</uri>
          </mesh>
        </geometry>
        <material>
          <diffuse>1 1 1 1</diffuse>
          <ambient>1 1 1 1</ambient>
        </material>
      </visual>
    </link>

      <joint name='camera_joint' type='fixed'>
        <pose relative_to="frame_base_link">0.17507416 -0.1 0.25 0 0 1.5707963</pose>
	<parent>frame_base_link</parent>
        <child>camera_link</child>
      </joint>

      <link name="camera_link">
        <pose relative_to="camera_joint">0 0 0 0 0 0</pose>
        <inertial>
          <mass>0.1</mass>
          <inertia>
            <ixx>0.000166667</ixx>
            <iyy>0.000166667</iyy>
            <izz>0.000166667</izz>
          </inertia>
        </inertial>
        <collision name="collision">
          <geometry>
            <box>
              <size>0.1 0.1 0.1</size>
            </box>
          </geometry>
        </collision>
        <visual name="visual">
          <geometry>
            <box>
              <size>0.1 0.1 0.1</size>
            </box>
          </geometry>
        </visual>
        <sensor name='intel realsense d435i' type='camera'>
          <camera>
            <save enabled='true'>
              <path>/tmp/camera_images</path>
	    </save>
	    <horizontal_fov>1.047</horizontal_fov>
	    <image>
              <width>1920</width>
	      <height>1080</height>
	    </image>
	    <clip>
              <near>0.1</near>
              <far>100</far>
            </clip>
          </camera>
	  <always_on>1</always_on>
	  <update_rate>30</update_rate>
          <visualize>true</visualize>
        </sensor>
      </link>
 
      <joint name='ultrasonic_1_joint' type='fixed'>
        <pose relative_to="frame_base_link">0.43724916124044599 -0.05 0.25 0 0 1.5707963</pose>
	<parent>frame_base_link</parent>
        <child>ultrasonic_1_link</child>
      </joint>

    <link name="ultrasonic_1_link">
      <pose relative_to="ultrasonic_1_joint">0 0 0 0 0 0</pose>
      <visual name="visual">
        <geometry>
          <box>
            <size>0.05 0.05 0.05</size>
          </box>
        </geometry>
      </visual>
      <sensor name='ultrasonic_1' type='gpu_lidar'>
        <pose>0 0 0 0 0 0</pose>
        <visualize>true</visualize>
        <always_on>true</always_on>
	<gz_frame_id>ultrasonic_1_link</gz_frame_id>
        <update_rate>10</update_rate>
        <lidar>
          <scan>
            <horizontal>
              <samples>5</samples>
              <resolution>1</resolution>
              <min_angle>-0.12</min_angle>
              <max_angle>0.12</max_angle>
            </horizontal>
            <vertical>
              <samples>5</samples>
              <resolution>1</resolution>
              <min_angle>-0.01</min_angle>
              <max_angle>0.01</max_angle>
            </vertical>
          </scan>
          <range>
            <min>0.02</min>
            <max>4</max>
            <resolution>0.01</resolution>
          </range>
	  <!--noise>
	    <type>gaussian</type>
	    <mean>0.0</mean>
	    <stddev>0.1</stddev>
	  </noise-->
	</lidar>
      </sensor>
    </link>

      <joint name='ultrasonic_2_joint' type='fixed'>
        <pose relative_to="frame_base_link">-0.087154396196859801 -0.05 0.25 0 0 1.5707963</pose>
	<parent>frame_base_link</parent>
        <child>ultrasonic_2_link</child>
      </joint>

    <link name="ultrasonic_2_link">
      <pose relative_to="ultrasonic_2_joint">0 0 0 0 0 0</pose>
      <visual name="visual">
        <geometry>
          <box>
            <size>0.05 0.05 0.05</size>
          </box>
        </geometry>
      </visual>
      <sensor name='ultrasonic_2' type='gpu_lidar'>
        <pose>0 0 0 0 0 0</pose>
        <visualize>true</visualize>
        <always_on>true</always_on>
	<gz_frame_id>ultrasonic_2_link</gz_frame_id>
        <update_rate>10</update_rate>
        <lidar>
          <scan>
            <horizontal>
              <samples>5</samples>
              <resolution>1</resolution>
              <min_angle>-0.12</min_angle>
              <max_angle>0.12</max_angle>
            </horizontal>
            <vertical>
              <samples>5</samples>
              <resolution>1</resolution>
              <min_angle>-0.01</min_angle>
              <max_angle>0.01</max_angle>
            </vertical>
          </scan>
          <range>
            <min>0.02</min>
            <max>4</max>
            <resolution>0.01</resolution>
          </range>
	  <!--noise>
	    <type>gaussian</type>
	    <mean>0.0</mean>
	    <stddev>0.1</stddev>
	  </noise-->
	</lidar>
      </sensor>
    </link>

      <joint name='ultrasonic_3_joint' type='fixed'>
        <pose relative_to="frame_base_link">0.43724916124044599 -0.35 0.25 0 0 -1.5707963</pose>
	<parent>frame_base_link</parent>
        <child>ultrasonic_3_link</child>
      </joint>

    <link name="ultrasonic_3_link">
      <pose relative_to="ultrasonic_3_joint">0 0 0 0 0 0</pose>
      <visual name="visual">
        <geometry>
          <box>
            <size>0.05 0.05 0.05</size>
          </box>
        </geometry>
      </visual>
      <sensor name='ultrasonic_3' type='gpu_lidar'>
        <pose>0 0 0 0 0 0</pose>
        <visualize>true</visualize>
        <always_on>true</always_on>
	<gz_frame_id>ultrasonic_3_link</gz_frame_id>
        <update_rate>10</update_rate>
        <lidar>
          <scan>
            <horizontal>
              <samples>5</samples>
              <resolution>1</resolution>
              <min_angle>-0.12</min_angle>
              <max_angle>0.12</max_angle>
            </horizontal>
            <vertical>
              <samples>5</samples>
              <resolution>1</resolution>
              <min_angle>-0.01</min_angle>
              <max_angle>0.01</max_angle>
            </vertical>
          </scan>
          <range>
            <min>0.02</min>
            <max>4</max>
            <resolution>0.01</resolution>
          </range>
	  <!--noise>
	    <type>gaussian</type>
	    <mean>0.0</mean>
	    <stddev>0.1</stddev>
	  </noise-->
	</lidar>
      </sensor>
    </link>

      <joint name='ultrasonic_4_joint' type='fixed'>
        <pose relative_to="frame_base_link">-0.087154396196859801 -0.35 0.25 0 0 -1.5707963</pose>
	<parent>frame_base_link</parent>
        <child>ultrasonic_4_link</child>
      </joint>

    <link name="ultrasonic_4_link">
      <pose relative_to="ultrasonic_4_joint">0 0 0 0 0 0</pose>
      <visual name="visual">
        <geometry>
          <box>
            <size>0.05 0.05 0.05</size>
          </box>
        </geometry>
      </visual>
      <sensor name='ultrasonic_4' type='gpu_lidar'>
        <pose>0 0 0 0 0 0</pose>
        <visualize>true</visualize>
        <always_on>true</always_on>
	<gz_frame_id>ultrasonic_4_link</gz_frame_id>
        <update_rate>10</update_rate>
        <lidar>
          <scan>
            <horizontal>
              <samples>5</samples>
              <resolution>1</resolution>
              <min_angle>-0.12</min_angle>
              <max_angle>0.12</max_angle>
            </horizontal>
            <vertical>
              <samples>5</samples>
              <resolution>1</resolution>
              <min_angle>-0.01</min_angle>
              <max_angle>0.01</max_angle>
            </vertical>
          </scan>
          <range>
            <min>0.02</min>
            <max>4</max>
            <resolution>0.01</resolution>
          </range>
	  <!--noise>
	    <type>gaussian</type>
	    <mean>0.0</mean>
	    <stddev>0.1</stddev>
	  </noise-->
	</lidar>
      </sensor>
    </link>



      <plugin
        filename="ignition-gazebo-diff-drive-system"
        name="ignition::gazebo::systems::DiffDrive">
        <left_joint>wheel0_joint</left_joint>
        <right_joint>wheel1_joint</right_joint>
        <wheel_separation>0.52435</wheel_separation>
        <wheel_radius>0.081</wheel_radius>
        <odom_publish_frequency>1</odom_publish_frequency>
        <max_linear_acceleration>1</max_linear_acceleration>
        <min_linear_acceleration>-1</min_linear_acceleration>
        <max_angular_acceleration>2</max_angular_acceleration>
        <min_angular_acceleration>-2</min_angular_acceleration>
        <max_linear_velocity>0.5</max_linear_velocity>
        <min_linear_velocity>-0.5</min_linear_velocity>
        <max_angular_velocity>1</max_angular_velocity>
        <min_angular_velocity>-1</min_angular_velocity>
      </plugin>

      <plugin
        filename="gz-sim-joint-state-publisher-system"
        name="gz::sim::systems::JointStatePublisher">
      </plugin>

      <plugin
        filename="gz-sim-pose-publisher-system"
        name="gz::sim::systems::PosePublisher">
        <publish_link_pose>true</publish_link_pose>
        <use_pose_vector_msg>true</use_pose_vector_msg>
        <static_publisher>true</static_publisher>
        <static_update_frequency>1</static_update_frequency>
      </plugin>

      <plugin
        filename="gz-sim-odometry-publisher-system"
        name="gz::sim::systems::OdometryPublisher">
      <odom_frame>odom</odom_frame>
      <robot_base_frame>frame_base_link</robot_base_frame>
      </plugin>

  </model>
</sdf>
