<?xml version="1.0" encoding="utf-8"?>
<!-- This URDF was automatically created by SolidWorks to URDF Exporter! Originally created by Stephen Brawner (brawner@gmail.com) 
     Commit Version: 1.6.0-4-g7f85cfe  Build Version: 1.6.7995.38578
     For more information, please see http://wiki.ros.org/sw_urdf_exporter -->
<robot name="diff_drive">
  <link name="base_link" />
  
  <joint name="base_to_frame" type="fixed">
    <parent link="base_link"/>
    <child link="frame_base_link"/>
    <origin 
       xyz="0 0 0"
       rpy="0 0 4.71238898" />
  </joint>

  <link name="frame_base_link">
    <inertial>
      <origin
        xyz="0.174583511826173 -0.270531094679587 0.175759169493147"
        rpy="0 0 0" />
      <mass
        value="10.5515252104505" />
      <inertia
        ixx="0.0587549778491583"
        ixz="1.57700965559471E-09"
        ixy="-1.55558247097524E-07"
        izz="0.196769177641087"
        iyz="-9.37394462552013E-07"
        iyy="0.145732241183979" />
    </inertial>
    <visual>
      <origin
        xyz="0 0 0"
        rpy="0 0 0" />
      <geometry>
        <mesh
		filename="file:///home/elias/git/robotics-minor/src/gazebo/ros_gz_description/models/meshes/frame_base_link.STL" />
      </geometry>
      <material name="">
        <color rgba="0.792156862745098 0.819607843137255 0.933333333333333 1" />
      </material>
    </visual>
    <collision>
      <origin
        xyz="0 0 0"
        rpy="0 0 0" />
      <geometry>
        <mesh
		filename="file:///home/elias/git/robotics-minor/src/gazebo/ros_gz_description/models/meshes/frame_base_link.STL" />
      </geometry>
    </collision>
  </link>

  <link
    name="left_wheel">
    <inertial>
      <origin
        xyz="-5.5511E-17 -0.036555 2.7756E-17"
        rpy="0 0 0" />
      <mass
        value="0.34293" />
      <inertia
        ixx="0.00040794"
        ixy="5.7218E-22"
        ixz="-1.3553E-20"
        iyy="0.00069254"
        iyz="9.0006E-20"
        izz="0.00040794" />
    </inertial>
    <visual>
      <origin
        xyz="0 0 0"
        rpy="0 0 0" />
      <geometry>
        <mesh
		filename="file:///home/elias/git/robotics-minor/src/gazebo/ros_gz_description/models/meshes/wheel0.STL" />
      </geometry>
      <material
        name="">
        <color
          rgba="1 1 1 1" />
      </material>
    </visual>
    <collision>
      <origin
        xyz="0 0 0"
        rpy="0 0 0" />
      <geometry>
        <mesh
		filename="file:///home/elias/git/robotics-minor/src/gazebo/ros_gz_description/models/meshes/wheel0.STL" />
      </geometry>
    </collision>
  </link>
  <joint
    name="left_wheel_joint"
    type="continuous">
    <origin
      xyz="0.437249161240446 -0.155403500268594 0.138082115205387"
      rpy="3.14159265358979 -0.452659618711459 -1.5707963267949" />
    <parent
      link="frame_base_link" />
    <child
      link="left_wheel" />
    <axis
      xyz="0 1 0" />
  </joint>
  <link
    name="right_wheel">
    <inertial>
      <origin
        xyz="1.3878E-17 -0.036555 0"
        rpy="0 0 0" />
      <mass
        value="0.34293" />
      <inertia
        ixx="0.00040794"
        ixy="4.1413E-21"
        ixz="-1.0842E-19"
        iyy="0.00069254"
        iyz="4.1465E-20"
        izz="0.00040794" />
    </inertial>
    <visual>
      <origin
        xyz="0 0 0"
        rpy="0 0 0" />
      <geometry>
        <mesh
		filename="file:///home/elias/git/robotics-minor/src/gazebo/ros_gz_description/models/meshes/wheel1.STL" />
      </geometry>
      <material
        name="">
        <color
          rgba="1 1 1 1" />
      </material>
    </visual>
    <collision>
      <origin
        xyz="0 0 0"
        rpy="0 0 0" />
      <geometry>
        <mesh
		filename="file:///home/elias/git/robotics-minor/src/gazebo/ros_gz_description/models/meshes/wheel1.STL" />
      </geometry>
    </collision>
  </link>
  <joint
    name="right_wheel_joint"
    type="continuous">
    <origin
      xyz="-0.0871543961968598 -0.155403500268594 0.138082115205387"
      rpy="0 1.00456422093585 -1.5707963267949" />
    <parent
      link="frame_base_link" />
    <child
      link="right_wheel" />
    <axis
      xyz="0 1 0" />
  </joint>

      <plugin
        filename="ignition-gazebo-diff-drive-system"
        name="ignition::gazebo::systems::DiffDrive">
        <left_joint>left_wheel_joint</left_joint>
	<right_joint>right_wheel_joint</right_joint>
        <wheel_separation>0.52435</wheel_separation>
        <wheel_radius>0.081</wheel_radius>
        <odom_publish_frequency>1</odom_publish_frequency>
	<topic>cmd_vel</topic>
      </plugin>
</robot>
