<?xml version="1.0" ?>
<sdf version='1.11'>
  <model name='diff_drive'>
    <link name='frame_base_link'>
      <inertial>
        <pose>0.17458351182617299 -0.27053109467958703 0.17575916949314699 0 0 0</pose>
        <mass>10.5515252104505</mass>
        <inertia>
          <ixx>0.058754977849158299</ixx>
          <ixy>0</ixy>
          <ixz>0</ixz>
          <iyy>0.14573224118397901</iyy>
          <iyz>0</iyz>
          <izz>0.19676917764108701</izz>
        </inertia>
      </inertial>
      <collision name='frame_base_link_collision'>
        <pose>0 0 0 0 0 0</pose>
        <geometry>
          <mesh>
            <scale>1 1 1</scale>
            <uri>file:///home/elias/git/robotics-minor/src/gazebo/ros_gz_description/models/meshes/frame_base_link.STL</uri>
          </mesh>
        </geometry>
      </collision>
      <visual name='frame_base_link_visual'>
        <pose>0 0 0 0 0 0</pose>
        <geometry>
          <mesh>
            <scale>1 1 1</scale>
            <uri>file:///home/elias/git/robotics-minor/src/gazebo/ros_gz_description/models/meshes/frame_base_link.STL</uri>
          </mesh>
        </geometry>
        <material>
          <diffuse>0.990196109 1 1 1</diffuse>
          <ambient>0.990196109 1 1 1</ambient>
        </material>
      </visual>
    </link>
    <joint name='joint0' type='revolute'>
      <pose relative_to='frame_base_link'>0.43724916124044599 -0.15540350026859401 0.13808211520538699 3.14159265358979 -0.45265961871145888 -1.5707963267949001</pose>
      <parent>frame_base_link</parent>
      <child>wheel0</child>
      <axis>
        <xyz>0 1 0</xyz>
        <limit>
          <lower>-inf</lower>
          <upper>inf</upper>
        </limit>
        <dynamics>
          <spring_reference>0</spring_reference>
          <spring_stiffness>0</spring_stiffness>
        </dynamics>
      </axis>
    </joint>
    <link name='wheel0'>
      <pose relative_to='joint0'>0 0 0 0 0 0</pose>
      <inertial>
        <pose>0 0 0 0 0 0</pose>
        <mass>0.34293000000000001</mass>
        <inertia>
          <ixx>0.00040793999999999997</ixx>
          <ixy>0</ixy>
          <ixz>0</ixz>
          <iyy>0.00069253999999999995</iyy>
          <iyz>0</iyz>
          <izz>0.00040793999999999997</izz>
        </inertia>
      </inertial>
      <collision name='wheel0_collision'>
        <pose>0 0 0 0 0 0</pose>
        <geometry>
          <mesh>
            <scale>1 1 1</scale>
            <uri>file:///home/elias/git/robotics-minor/src/gazebo/ros_gz_description/models/meshes/wheel0.STL</uri>
          </mesh>
        </geometry>
      </collision>
      <visual name='wheel0_visual'>
        <pose>0 0 0 0 0 0</pose>
        <geometry>
          <mesh>
            <scale>1 1 1</scale>
            <uri>file:///home/elias/git/robotics-minor/src/gazebo/ros_gz_description/models/meshes/wheel0.STL</uri>
          </mesh>
        </geometry>
        <material>
          <diffuse>1 1 1 1</diffuse>
          <ambient>1 1 1 1</ambient>
        </material>
      </visual>
    </link>
    <joint name='joint1' type='revolute'>
      <pose relative_to='frame_base_link'>-0.087154396196859801 -0.15540350026859401 0.13808211520538699 0 1.0045642209358503 -1.5707963267949001</pose>
      <parent>frame_base_link</parent>
      <child>wheel1</child>
      <axis>
        <xyz>0 -1 0</xyz>
        <limit>
          <lower>-inf</lower>
          <upper>inf</upper>
        </limit>
        <dynamics>
          <spring_reference>0</spring_reference>
          <spring_stiffness>0</spring_stiffness>
        </dynamics>
      </axis>
    </joint>
    <link name='wheel1'>
      <pose relative_to='joint1'>0 0 0 0 0 0</pose>
      <inertial>
        <pose>0 0 0 0 0 0</pose>
        <mass>0.34293000000000001</mass>
        <inertia>
          <ixx>0.00040793999999999997</ixx>
          <ixy>0</ixy>
          <ixz>0</ixz>
          <iyy>0.00069253999999999995</iyy>
          <iyz>0</iyz>
          <izz>0.00040793999999999997</izz>
        </inertia>
      </inertial>
      <collision name='wheel1_collision'>
        <pose>0 0 0 0 0 0</pose>
        <geometry>
          <mesh>
            <scale>1 1 1</scale>
            <uri>file:///home/elias/git/robotics-minor/src/gazebo/ros_gz_description/models/meshes/wheel1.STL</uri>
          </mesh>
        </geometry>
      </collision>
      <visual name='wheel1_visual'>
        <pose>0 0 0 0 0 0</pose>
        <geometry>
          <mesh>
            <scale>1 1 1</scale>
            <uri>file:///home/elias/git/robotics-minor/src/gazebo/ros_gz_description/models/meshes/wheel1.STL</uri>
          </mesh>
        </geometry>
        <material>
          <diffuse>1 1 1 1</diffuse>
          <ambient>1 1 1 1</ambient>
        </material>
      </visual>
    </link>

      <plugin
        filename="ignition-gazebo-diff-drive-system"
        name="ignition::gazebo::systems::DiffDrive">
        <left_joint>joint0</left_joint>
        <right_joint>joint1</right_joint>
        <wheel_separation>0.52435</wheel_separation>
        <wheel_radius>0.081</wheel_radius>
        <odom_publish_frequency>1</odom_publish_frequency>
        <max_linear_acceleration>1</max_linear_acceleration>
        <min_linear_acceleration>-1</min_linear_acceleration>
        <max_angular_acceleration>2</max_angular_acceleration>
        <min_angular_acceleration>-2</min_angular_acceleration>
        <max_linear_velocity>0.5</max_linear_velocity>
        <min_linear_velocity>-0.5</min_linear_velocity>
        <max_angular_velocity>1</max_angular_velocity>
        <min_angular_velocity>-1</min_angular_velocity>
      </plugin>
  </model>
</sdf>
